[2022-09-17 13:47:55,382] {taskinstance.py:1159} INFO - Dependencies all met for <TaskInstance: user_processing.create_table manual__2022-09-17T13:47:47.239265+00:00 [queued]>
[2022-09-17 13:47:55,396] {taskinstance.py:1159} INFO - Dependencies all met for <TaskInstance: user_processing.create_table manual__2022-09-17T13:47:47.239265+00:00 [queued]>
[2022-09-17 13:47:55,396] {taskinstance.py:1356} INFO - 
--------------------------------------------------------------------------------
[2022-09-17 13:47:55,396] {taskinstance.py:1357} INFO - Starting attempt 1 of 1
[2022-09-17 13:47:55,396] {taskinstance.py:1358} INFO - 
--------------------------------------------------------------------------------
[2022-09-17 13:47:55,416] {taskinstance.py:1377} INFO - Executing <Task(PostgresOperator): create_table> on 2022-09-17 13:47:47.239265+00:00
[2022-09-17 13:47:55,425] {standard_task_runner.py:52} INFO - Started process 97 to run task
[2022-09-17 13:47:55,447] {standard_task_runner.py:79} INFO - Running: ['***', 'tasks', 'run', 'user_processing', 'create_table', 'manual__2022-09-17T13:47:47.239265+00:00', '--job-id', '5', '--raw', '--subdir', 'DAGS_FOLDER/user_processing.py', '--cfg-path', '/tmp/tmphg1inwle', '--error-file', '/tmp/tmpd1l2vm5p']
[2022-09-17 13:47:55,450] {standard_task_runner.py:80} INFO - Job 5: Subtask create_table
[2022-09-17 13:47:55,541] {task_command.py:369} INFO - Running <TaskInstance: user_processing.create_table manual__2022-09-17T13:47:47.239265+00:00 [running]> on host 9f5a23719b96
[2022-09-17 13:47:55,707] {taskinstance.py:1571} INFO - Exporting the following env vars:
AIRFLOW_CTX_DAG_OWNER=***
AIRFLOW_CTX_DAG_ID=user_processing
AIRFLOW_CTX_TASK_ID=create_table
AIRFLOW_CTX_EXECUTION_DATE=2022-09-17T13:47:47.239265+00:00
AIRFLOW_CTX_TRY_NUMBER=1
AIRFLOW_CTX_DAG_RUN_ID=manual__2022-09-17T13:47:47.239265+00:00
[2022-09-17 13:47:56,142] {taskinstance.py:1889} ERROR - Task failed with exception
Traceback (most recent call last):
  File "/home/airflow/.local/lib/python3.7/site-packages/airflow/providers/postgres/operators/postgres.py", line 92, in execute
    self.hook.run(self.sql, self.autocommit, parameters=self.parameters)
  File "/home/airflow/.local/lib/python3.7/site-packages/airflow/hooks/dbapi.py", line 181, in run
    with closing(self.get_conn()) as conn:
  File "/home/airflow/.local/lib/python3.7/site-packages/airflow/providers/postgres/hooks/postgres.py", line 86, in get_conn
    conn = deepcopy(self.connection or self.get_connection(conn_id))
  File "/home/airflow/.local/lib/python3.7/site-packages/airflow/hooks/base.py", line 67, in get_connection
    conn = Connection.get_connection_from_secrets(conn_id)
  File "/home/airflow/.local/lib/python3.7/site-packages/airflow/models/connection.py", line 430, in get_connection_from_secrets
    raise AirflowNotFoundException(f"The conn_id `{conn_id}` isn't defined")
airflow.exceptions.AirflowNotFoundException: The conn_id `postgres` isn't defined
[2022-09-17 13:47:56,193] {taskinstance.py:1400} INFO - Marking task as FAILED. dag_id=user_processing, task_id=create_table, execution_date=20220917T134747, start_date=20220917T134755, end_date=20220917T134756
[2022-09-17 13:47:56,312] {standard_task_runner.py:97} ERROR - Failed to execute job 5 for task create_table (The conn_id `postgres` isn't defined; 97)
[2022-09-17 13:47:56,356] {local_task_job.py:156} INFO - Task exited with return code 1
[2022-09-17 13:47:56,503] {local_task_job.py:273} INFO - 0 downstream tasks scheduled from follow-on schedule check
